Workbook

Sheet Bulk Upload

Sheet Dashboard
B2: iNeuBytes • SEO + Social Task Dashboard
B4: Site | C4: Items | D4: Issues (YES) | E4: Passed (NO) | F4: High Issues | G4: Completion %
B5: Website 1 | C5: ='Website 1'!H14 -> 18 | D5: ='Website 1'!H16 -> 10 | E5: ='Website 1'!H17 -> 9 | F5: ='Website 1'!H18 -> 1 | G5: ='Website 1'!H19 -> 0.52631579
B6: Website 2 | C6: ='Website 2'!H14 -> 18 | D6: ='Website 2'!H16 -> 10 | E6: ='Website 2'!H17 -> 9 | F6: ='Website 2'!H18 -> 0 | G6: ='Website 2'!H19 -> 0.52631579
B7: Website 3 | C7: ='Website 3'!H14 -> 18 | D7: ='Website 3'!H16 -> 9 | E7: ='Website 3'!H17 -> 10 | F7: ='Website 3'!H18 -> 1 | G7: ='Website 3'!H19 -> 0.47368421
B8: TOTAL | C8: =SUM(C5:C7) -> 54 | D8: =SUM(D5:D7) -> 29 | E8: =SUM(E5:E7) -> 28 | F8: =SUM(F5:F7) -> 2 | G8: =AVERAGE(G5:G7) -> 0.50877193
B27: Tip: fill in the YES/NO answers on each Website sheet — these totals update automatically.

Sheet TASK 1
A1: TASK 1

Sheet Website 1
A1: Main Contact Name | B1: Customers support | D1: Facebook URL | E1: https://m.facebook.com/boat.lifestyle/
A2: Main Email Address | B2: support@boat-lifestyle.com | D2: Twitter URL | E2: https://x.com/RockWithboAt
A3: Business Name | B3: boAt | D3: Linkedin URL | E3: https://linkedin.com/company/boat-lifestyle
A4: Street adress | B4: Maker Chambers V, Nariman Point | D4: YouTube URL | E4: https://youtube.com/@boat-lifestyle?si=tg5WT2eVHwtmGCpk
A5: Country | B5: India | D5: Instagram URL | E5: https://www.instagram.com/boat.nirvana/
A6: City | B6: Mumbai | D6: Pinterest URL | E6: N/A
A7: Post Code | B7: 400021 | D7: 3 competitors sites as per research | E7: Noise,boult,jbl
A8: State | B8: Maharashtra | D8: Keyword people search to find about business | E8: wireless earbuds, headphones, smartwatches,boat lifestyle
A9: Phone Number | B9: +91 22-66288000 | D9: Products or servcies offered | E9: Earbuds, headphones, smartwatches, speakers
A10: Website Address | B10: https://www.boat-lifestyle.com/ | D10: Payment Methods accepted | E10: UPI, Cards, Net Banking, Wallets, EMI
A11: Opening hours | B11: N/A(online store) | D11: Year Established | E11: November -2016
A13: SEO CHECKLIST | G13: LIVE PROGRESS TRACKER
A14: PRIORITY | B14: NO. | C14: CHECKLIST | D14: ISSUE EXISTS (YES/NO) | E14: RESOURCES | G14: Total checklist items | H14: =COUNTA(C16:C36)-3 -> 18
C15: On-Page/Technical SEO Elements | G15: Answered | H15: =COUNTIF(D16:D36,"YES")+COUNTIF(D16:D36,"NO") -> 19
A16: LOW | B16: 1 | C16: Is there single H1 heading for each page? | D16: YES | E16: SEOBILITY, UBERSUGGEST | G16: Issues found (YES) | H16: =COUNTIF(D16:D36,"YES") -> 10
A17: LOW | B17: 2 | C17: Have the H-tags, paragraphs been inserted in chronologically descending order? | D17: YES | E17: SEOBILITY, UBERSUGGEST | G17: Passed (NO) | H17: =COUNTIF(D16:D36,"NO") -> 9
A18: LOW | B18: 3 | C18: Does each URL have an individual meta description? | D18: YES | E18: SEOBILITY, UBERSUGGEST | G18: High priority issues | H18: =_xlfn.countifs(A16:A36,"HIGH",D16:D36,"YES") -> 1
A19: LOW | B19: 4 | C19: Are meta title unique for each page? | D19: YES | E19: SEOBILITY, UBERSUGGEST | G19: Completion % | H19: =IF(H15=0,0,H16/H15) -> 0.52631579
A20: LOW | B20: 5 | C20: Meta description are compelling and unique? | D20: YES | E20: SEOBILITY, UBERSUGGEST
A21: LOW | B21: 6 | C21: Have you exhausted the maximum length of over 250 characters per description? | D21: NO | E21: SEOBILITY, UBERSUGGEST
A22: LOW | B22: 7 | C22: Does the URL, meta-title and meta-description contain the focus keyword of the page? | D22: YES | E22: SEOBILITY, UBERSUGGEST
A23: LOW | B23: 8 | C23: Used focus keyword in first paragraph? | D23: YES | E23: SEOBILITY, UBERSUGGEST
A24: LOW | B24: 9 | C24: Are URLs as short as possible? | D24: YES | E24: SEOBILITY, UBERSUGGEST
A25: MEDIUM | B25: 10 | C25: Is the page speed optimized? | D25: YES | E25: Google Page Speed Insights
A26: MEDIUM | B26: 11 | C26: Are image sizes optimized? | D26: NO | E26: Google Page Speed Insights
A27: MEDIUM | B27: 12 | C27: Make your content easy to share (Social Share) | D27: NO | E27: SEOBILITY, UBERSUGGEST
A28: MEDIUM | B28: 13 | C28: Are redirections working properly? | D28: NO | E28: Small SEO Tools - REDIRECT CHECKER
A29: HIGH | B29: 14 | C29: Check for broken links | D29: YES | E29: https://www.drlinkcheck.com/
C30: LOCAL SEO Elements
A31: LOW | B31: 15 | C31: Is business listed on Google my business | D31: NO | E31: Google my business
A32: LOW | B32: 16 | C32: Is business listed on Bing? | D32: NO | E32: Bing
C33: USER EXPERIENCE
A34: MEDIUM | B34: 17 | C34: Do you have call to action? | D34: NO | E34: Website
A35: MEDIUM | B35: 18 | C35: Is favicon aded? | D35: NO | E35: https://sitechecker.pro/what-is-favicon/
A36: MEDIUM | B36: 19 | C36: Company location and contact information are accessible from the homepage | D36: NO | E36: Website
A37: HIGH | B37: 20 | C37: Do you have custom 404 page? | D37: No | E37: 404page – your smart custom 404 error page

Sheet Website 2
A1: Main Contact Name | B1: Customers Support | D1: Facebook URL | E1: https://facebook.com/Gonoise
A2: Main Email Address | B2: support@goniose.com | D2: Twitter URL | E2: https://x.com/gonoise
A3: Business Name | B3: Noise | D3: Linkedin URL | E3: https://linkedin.com/company/gonoise-com
A4: Street adress | B4: Two Horizon Center, Golf Course Road | D4: YouTube URL | E4: https://youtube.com/@gonoise_official?si=eGW94LEYULxlsRha
A5: Country | B5: India | D5: Instagram URL | E5: https://www.instagram.com/go_noise/
A6: City | B6: Gurugram | D6: Pinterest URL | E6: N/A
A7: Post Code | B7: 122003 | D7: 3 competitors sites as per research | E7: boAt,Boult,Fire-Boltt
A8: State | B8: Haryana | D8: Keyword people search to find about business | E8: smartwatches, earbuds, wearables earbuds, headphones, speakers
A9: Phone Number | B9: +91 8882132132 | D9: Products or servcies offered | E9: Smartwatches, Earbuds, Smart Rings
A10: Website Address | B10: https://www.gonoise.com | D10: Payment Methods accepted | E10: UPI, Cards, Net Banking, Wallets
A11: Opening hours | B11: N/A (online store) | D11: Year Established | E11: 2014
A13: SEO CHECKLIST | G13: LIVE PROGRESS TRACKER
A14: PRIORITY | B14: NO. | C14: CHECKLIST | D14: ISSUE EXISTS (YES/NO) | E14: RESOURCES | G14: Total checklist items | H14: =COUNTA(C16:C36)-3 -> 18
C15: On-Page/Technical SEO Elements | G15: Answered | H15: =COUNTIF(D16:D36,"YES")+COUNTIF(D16:D36,"NO") -> 19
A16: LOW | B16: 1 | C16: Is there single H1 heading for each page? | D16: YES | E16: SEOBILITY, UBERSUGGEST | G16: Issues found (YES) | H16: =COUNTIF(D16:D36,"YES") -> 10
A17: LOW | B17: 2 | C17: Have the H-tags, paragraphs been inserted in chronologically descending order? | D17: YES | E17: SEOBILITY, UBERSUGGEST | G17: Passed (NO) | H17: =COUNTIF(D16:D36,"NO") -> 9
A18: LOW | B18: 3 | C18: Does each URL have an individual meta description? | D18: YES | E18: SEOBILITY, UBERSUGGEST | G18: High priority issues | H18: =_xlfn.countifs(A16:A36,"HIGH",D16:D36,"YES") -> 0
A19: LOW | B19: 4 | C19: Are meta title unique for each page? | D19: YES | E19: SEOBILITY, UBERSUGGEST | G19: Completion % | H19: =IF(H15=0,0,H16/H15) -> 0.52631579
A20: LOW | B20: 5 | C20: Meta description are compelling and unique? | D20: YES | E20: SEOBILITY, UBERSUGGEST
A21: LOW | B21: 6 | C21: Have you exhausted the maximum length of over 250 characters per description? | D21: YES | E21: SEOBILITY, UBERSUGGEST
A22: LOW | B22: 7 | C22: Does the URL, meta-title and meta-description contain the focus keyword of the page? | D22: YES | E22: SEOBILITY, UBERSUGGEST
A23: LOW | B23: 8 | C23: Used focus keyword in first paragraph? | D23: YES | E23: SEOBILITY, UBERSUGGEST
A24: LOW | B24: 9 | C24: Are URLs as short as possible? | D24: YES | E24: SEOBILITY, UBERSUGGEST
A25: MEDIUM | B25: 10 | C25: Is the page speed optimized? | D25: YES | E25: Google Page Speed Insights
A26: MEDIUM | B26: 11 | C26: Are image sizes optimized? | D26: NO | E26: Google Page Speed Insights
A27: MEDIUM | B27: 12 | C27: Make your content easy to share (Social Share) | D27: NO | E27: SEOBILITY, UBERSUGGEST
A28: MEDIUM | B28: 13 | C28: Are redirections working properly? | D28: NO | E28: Small SEO Tools - REDIRECT CHECKER
A29: HIGH | B29: 14 | C29: Check for broken links | D29: NO | E29: https://www.drlinkcheck.com/
C30: LOCAL SEO Elements
A31: LOW | B31: 15 | C31: Is business listed on Google my business | D31: NO | E31: Google my business
A32: LOW | B32: 16 | C32: Is business listed on Bing? | D32: NO | E32: Bing
C33: USER EXPERIENCE
A34: MEDIUM | B34: 17 | C34: Do you have call to action? | D34: NO | E34: Website
A35: MEDIUM | B35: 18 | C35: Is favicon aded? | D35: NO | E35: https://sitechecker.pro/what-is-favicon/
A36: MEDIUM | B36: 19 | C36: Company location and contact information are accessible from the homepage | D36: NO | E36: Website
A37: HIGH | B37: 20 | C37: Do you have custom 404 page? | D37: No | E37: 404page – your smart custom 404 error page

Sheet Website 3
A1: Main Contact Name | B1: Customer support | D1: Facebook URL | E1: https://www.facebook.com/GOBOULT
A2: Main Email Address | B2: support@boultaudio.com | D2: Twitter URL | E2: N/A
A3: Business Name | B3: Boult | D3: Linkedin URL | E3: https://linkedin.com/company/boultaudio
A4: Street adress | B4: New Delhi (Corporate Office) | D4: YouTube URL | E4: https://youtube.com/@goboult?si=XFATJhbfacYrvr_6
A5: Country | B5: India | D5: Instagram URL | E5: https://www.instagram.com/goboult_official/
A6: City | B6: New Delhi | D6: Pinterest URL | E6: N/A
A7: Post Code | B7: 110001 | D7: 3 competitors sites as per research | E7: boAt,Noise,JBL
A8: State | B8: Delhi | D8: Keyword people search to find about business | E8: earbuds, headphones, speakers
A9: Phone Number | B9: +91 9289803880 | D9: Products or servcies offered | E9: Earbuds, Neckbands, Speakers, Smartwatches
A10: Website Address | B10: https://www.boultaudio.com | D10: Payment Methods accepted | E10: UPI, Cards, Net Banking, Wallets
A11: Opening hours | B11: N/A(online store) | D11: Year Established | E11: June2017
A13: SEO CHECKLIST | G13: LIVE PROGRESS TRACKER
A14: PRIORITY | B14: NO. | C14: CHECKLIST | D14: ISSUE EXISTS (YES/NO) | E14: RESOURCES | G14: Total checklist items | H14: =COUNTA(C16:C36)-3 -> 18
C15: On-Page/Technical SEO Elements | G15: Answered | H15: =COUNTIF(D16:D36,"YES")+COUNTIF(D16:D36,"NO") -> 19
A16: LOW | B16: 1 | C16: Is there single H1 heading for each page? | D16: YES | E16: SEOBILITY, UBERSUGGEST | G16: Issues found (YES) | H16: =COUNTIF(D16:D36,"YES") -> 9
A17: LOW | B17: 2 | C17: Have the H-tags, paragraphs been inserted in chronologically descending order? | D17: YES | E17: SEOBILITY, UBERSUGGEST | G17: Passed (NO) | H17: =COUNTIF(D16:D36,"NO") -> 10
A18: LOW | B18: 3 | C18: Does each URL have an individual meta description? | D18: YES | E18: SEOBILITY, UBERSUGGEST | G18: High priority issues | H18: =_xlfn.countifs(A16:A36,"HIGH",D16:D36,"YES") -> 1
A19: LOW | B19: 4 | C19: Are meta title unique for each page? | D19: YES | E19: SEOBILITY, UBERSUGGEST | G19: Completion % | H19: =IF(H15=0,0,H16/H15) -> 0.47368421
A20: LOW | B20: 5 | C20: Meta description are compelling and unique? | D20: YES | E20: SEOBILITY, UBERSUGGEST
A21: LOW | B21: 6 | C21: Have you exhausted the maximum length of over 250 characters per description? | D21: YES | E21: SEOBILITY, UBERSUGGEST
A22: LOW | B22: 7 | C22: Does the URL, meta-title and meta-description contain the focus keyword of the page? | D22: YES | E22: SEOBILITY, UBERSUGGEST
A23: LOW | B23: 8 | C23: Used focus keyword in first paragraph? | D23: YES | E23: SEOBILITY, UBERSUGGEST
A24: LOW | B24: 9 | C24: Are URLs as short as possible? | D24: NO | E24: SEOBILITY, UBERSUGGEST
A25: MEDIUM | B25: 10 | C25: Is the page speed optimized? | D25: NO | E25: Google Page Speed Insights
A26: MEDIUM | B26: 11 | C26: Are image sizes optimized? | D26: NO | E26: Google Page Speed Insights
A27: MEDIUM | B27: 12 | C27: Make your content easy to share (Social Share) | D27: NO | E27: SEOBILITY, UBERSUGGEST
A28: MEDIUM | B28: 13 | C28: Are redirections working properly? | D28: NO | E28: Small SEO Tools - REDIRECT CHECKER
A29: HIGH | B29: 14 | C29: Check for broken links | D29: YES | E29: https://www.drlinkcheck.com/
C30: LOCAL SEO Elements
A31: LOW | B31: 15 | C31: Is business listed on Google my business | D31: NO | E31: Google my business
A32: LOW | B32: 16 | C32: Is business listed on Bing? | D32: NO | E32: Bing
C33: USER EXPERIENCE
A34: MEDIUM | B34: 17 | C34: Do you have call to action? | D34: NO | E34: 42887
A35: MEDIUM | B35: 18 | C35: Is favicon aded? | D35: NO | E35: https://sitechecker.pro/what-is-favicon/
A36: MEDIUM | B36: 19 | C36: Company location and contact information are accessible from the homepage | D36: NO | E36: Website
A37: HIGH | B37: 20 | C37: Do you have custom 404 page? | D37: No | E37: 404page – your smart custom 404 error page

Sheet MAJOR PROJECT
A1: MAJOR PROJECT

Sheet Competitors Sheet
A1: MAJOR PROJECT | B1: Competitor Sheet
A2: Brand/Client | B2: INEUBYTES
A3: Objective | B3: PREPARING COMPETITORS
A4: Website | B4: www.ineubytes.com
A5: Date
A6: COMPETITORS LIST
A7: No. | B7: Competitors Name | C7: website Link | D7: Instagram Page | E7: Twitter Handle | F7: LinkedIn Page | G7: Facebook Handle
A8: 1 | B8: PrepBytes | C8: https://www.prepbytes.com/ | D8: https://www.instagram.com/prepbytes | E8: https://x.com/prepbytes0211 | F8: https://www.linkedin.com/company/prepbytes/ | G8: https://www.facebook.com/prepbytes0211/
A9: 2 | B9: internshala | C9: https://internshala.com/ | D9: https://www.instagram.com/internshala | E9: https://x.com/Internshala | F9: https://www.linkedin.com/company/internshala/ | G9: https://www.facebook.com/Internshala/
A10: 3 | B10: Unstop | C10: https://unstop.com | D10: https://www.instagram.com/unstop.world | E10: https://x.com/Unstop_World | F10: https://www.linkedin.com/company/unstop/ | G10: https://www.facebook.com/Unstop.World/
A11: 4 | B11: Eventbeep | C11: https://www.eventbeep.com/en | D11: https://www.instagram.com/beepappofficial | E11: https://x.com/event_beep | F11: https://www.linkedin.com/company/beepappofficial/ | G11: https://www.facebook.com/EventBeep/
A12: 5 | B12: Scaler | C12: https://www.scaler.com/ | D12: https://www.instagram.com/scaler_official | E12: https://x.com/scaler_official | F12: https://www.linkedin.com/school/scalerofficial/ | G12: https://www.facebook.com/scalerofficial/
A13: 6 | B13: Simplilearn | C13: https://www.simplilearn.com/ | D13: https://www.instagram.com/simplilearn_official | E13: https://x.com/simplilearn | F13: https://www.linkedin.com/company/simplilearn/ | G13: https://www.facebook.com/SimplilearnIndia/
A14: 7 | B14: Coding Blocks | C14: https://www.codingblocks.com/ | D14: https://www.instagram.com/codingblocks | E14: https://x.com/CodingBlocksIn | F14: https://www.linkedin.com/school/codingblocksindia/ | G14: https://www.facebook.com/codingblocksindia/
A15: 8 | B15: Upgrad | C15: https://www.upgrad.com/ | D15: https://www.instagram.com/upgrad_edu | E15: https://x.com/upGrad_edu | F15: https://www.linkedin.com/company/ueducation/ | G15: https://www.facebook.com/upGradGlobal/
A16: 9 | B16: Great learning | C16: https://www.mygreatlearning.com/ | D16: https://www.instagram.com/greatlearningofficial | E16: https://x.com/Great_Learning | F16: https://www.linkedin.com/school/great-learning/ | G16: https://www.facebook.com/GreatLearningOfficial/
A17: 10 | B17: Coding ninjas | C17: https://www.codingninjas.com/ | D17: https://www.instagram.com/coding.ninjas | E17: https://x.com/CodingNinjasOff | F17: https://www.linkedin.com/school/codingninjas/ | G17: https://www.facebook.com/codingninjas/

Sheet Ads Sheet
A1: Major Project (2 Weeks) : Developing and Implementing a Comprehensive Content Calendar ( Create 30 Posts )
A3: No. | B3: Post Type | C3: DATE | D3: TIME | E3: CAPTION (Content) | F3: Creative | G3: HASHTAG | H3: REFERENCE LINK
B4: Images | E4: 1 . Install the "Keywords Everywhere - Keyword Tool" Chrome extension for keyword data. 2. Identify relevant, high-volume keywords using this tool. 3. Use ChatGPT to craft engaging captions incorporating these keywords. 4. Remember: Captions should prioritize audience engagement and incorporate keywords naturally. | F4: Visual Creative : Canva | G4: https://blog.hootsuite.com/linkedin-hashtags-guide/ | H4: If you are using any looks like CANVA, you can share the viewable link otherwise you can take file and post in google drive and just share google drive file link
B5: Videos | F5: Copywriting Creative : Grammarly
B6: User-Generated Content (UGC) | F6: Video Creative : Openshot
B7: Carousels | F7: Audio Creative : Audacity
B8: How-to Guides/Tutorials | F8: Interactive Creative : Scratch
B9: Infographics | F9: Social Media Creative : Canva
B10: Live Videos | F10: Print Creative : Adobe Spark
B11: Memes | F11: Motion Graphics Creative : Powtoon
B12: Motivational/Inspirational content | F12: User Interface/User Experience (UI/UX) Creative : Figma
B13: Polls and Surveys
B14: Behind-the-Scenes
B15: Product Spotlight
B16: Case Studies/Testimonials
B17: Industry News/Updates
B18: Infotainment
B19: Seasonal/Holiday Content
B20: Guest Posts/Influencer Collaborations
B21: Contests/Giveaways
B22: Ask Me Anything (AMA)
B23: Educational Webinars/Workshops
A24: No. | B24: TYPE OF POST | C24: DATE | D24: TIME | E24: CAPTION (Content) | F24: CREATIVE TYPE | G24: HASHTAG | H24: REFERENCE LINK
A25: 1 | B25: Industry News/Updates | C25: (Sample) | D25: (Sample) | E25: 🌟 Exciting Industry Update: Data Science in Education and Technology! 📊💡🚀 🎓 As a passionate advocate for data-driven decision-making, I couldn't be more thrilled about the latest developments in data science for the education and technology industries. Let me share with you some incredible insights and personal experiences that highlight the power of data in transforming these sectors. 💻📚✨ 🔍 The Education Revolution: In the education industry, data science has emerged as a game-changer, propelling us into an era of personalized learning. 🎯📖 With the help of advanced analytics, educators can now tailor instructional approaches to meet individual students' needs. From adaptive learning platforms to intelligent tutoring systems, technology fueled by data insights is reshaping the classroom experience, unlocking students' full potential. 🌟🔓 🌐 The Tech Transformation: Meanwhile, in the technology industry, data science is the driving force behind innovation and digital transformation. 💡🚀 Companies are leveraging data analytics to extract actionable insights from vast amounts of information, enabling them to make smarter business decisions. From customer behavior analysis to predictive modeling, data science empowers organizations to optimize processes, enhance user experiences, and gain a competitive edge. 💼📊 🔬 Personal Journey: Reflecting on my own journey, I've witnessed firsthand how data science has revolutionized education and technology. During my time as an educator, data-driven insights helped me identify areas for improvement, tailoring my teaching strategies to address individual student needs. The impact was remarkable – increased engagement, improved learning outcomes, and a true sense of empowerment among my students. 🌟🎓 🌈 Let's Connect and Collaborate! I'd love | F25: Copywriting Creative | G25: #DataScience #EducationIndustry #TechnologyIndustry #DigitalTransformation #PersonalizedLearning #Innovation #DataDrivenDecisionMaking #ThoughtLeadership #IndustryInsights #EdTech #TechAdvancements | H25: No design needed
A26: 2 | B26: Images | C26: 08-06-20XX (Sample) | D26: 0.70833333 | E26: 📣 Calling all aspiring data wizards! 🧙‍♂️✨ Level up your skills with our exclusive 3-month data science course 📊🔬 Join us on a journey of discovery as we unravel the secrets of data analysis, machine learning, and more 🌟💻 Unleash your potential and gain a competitive edge in the digital era 🚀💡 Don't miss out on this golden opportunity! Register now and let the data adventure begin! 📚💫 | F26: Visual Creative | G26: #DataScienceJourney #DataWizards #LevelUpYourSkills #DataAnalysis #MachineLearning #UnleashYourPotential #DigitalEdge #DataAdventure #TechEducation #CareerGrowth | H26: https://www.canva.com/design/XXXXX
A27: Major Project (2 Weeks) : Developing and Implementing a Comprehensive Content Calendar ( Create 30 Posts )
A29: No. | B29: TYPE OF POST | C29: DATE | D29: TIME | E29: CAPTION (Content) | F29: CREATIVE TYPE | G29: HASHTAG | H29: REFERENCE LINK | J29: CALENDAR PROGRESS
A30: 1 | B30: Motivational/Inspirational content | C30: 46214 | D30: 0.70833333 | E30: Most businesses are sitting on diamonds. But without a polished social media presence, the world sees coal. Your product quality, your team, your vision — none of it matters if your online presence doesn't reflect it. Unpolished gems are treated like coals. The companies winning right now aren't always the best. They're the most visible. The most consistent. The ones who showed up online before they felt "ready." Your brand is the gem. Social media is the cutting and polishing. One makes you valuable. The other makes you seen. I learned while doing my #iNeuBytes internship That how much digital marketing is important for a brand. | F30: Visual Creative | G30: #iNeuBytes #BrandVisibility #SocialMediaMarketing #DigitalMarketing #ContentStrategy #iNeuBytes #PersonalBranding #MarketingMindset #SmallBusiness #StartupIndia #LinkedInMarketing | H30: No design needed | J30: Posts planned | K30: =COUNTA(B30:B59) -> 30
A31: 2 | B31: Motivational/Inspirational content | C31: 46214 | D31: 0.75 | E31: I've seen people post once a week and explode. I've seen others post three times a day with almost no growth. The difference isn't luck. It's context. Every successful creator has a unique mix of audience, timing, brand, and experience. So before you copy someone's content strategy, ask yourself: Will this work for my audience—or am I just copying because it worked for someone else? The best strategy isn't borrowed. It's built. ( While doing Competitor analysis task for my #iNeuBytes internship i learned same content doesn't always work for different brands, every brand needs to find their own.) | F31: Visual Creative | G31: #iNeuBytes #contentcreator #audience #growth | H31: No design needed | J31: Captions written | K31: =COUNTA(E30:E59) -> 30
A32: 3 | B32: Infographic | C32: 46215 | D32: 0.70833333 | E32: Everybody knows the line: "Have a break, have a KitKat." But have you ever wondered why you still remember it years later? That's the power of a great jingle. A jingle isn't just a catchy tune or phrase. It's a memory trigger. It helps people recognize a brand, creates familiarity, and makes advertisements stick long after they're over. When done right, a jingle turns marketing into memory. That's why some of the most successful brands invest in creating sounds and phrases people can instantly recall. People may forget an advertisement. They rarely forget a great jingle. What's the first brand jingle that comes to your mind? (While Doing my iNeuBytes internship i realised that the most engaging thing about an advertisement is not just its design, content and hook the music the jingle and sound branding also matters.) | F32: Visual Creative | G32: #iNeuBytes #onlineinternship #iNeuBytesintership #ContentCreation #Marketing #Branding #Advertising #Jingles #BrandRecall #KitKat #ConsumerPsychology | H32: No design needed | J32: Creatives linked | K32: =COUNTA(H30:H59) -> 30
A33: 4 | B33: Motivational/Inspirational content | C33: 46215 | D33: 0.75 | E33: Think of it this way: 📜 Certificates are your entry pass. 🛠️ Skills are your toolkit. 📈 Experience is your proof. Without the pass, some doors stay closed. Without the toolkit, you can't do the work. Without experience, it's difficult to earn trust. Build all three—but spend most of your time sharpening your skills. (Thanks to my iNeuBytes internship, I understand the difference between holding a certificate and having a skill.) | F33: Visual Creative | G33: #iNeuBytes #internship #certificates #iNeuBytesinternship #skills | H33: No design needed | J33: Target | K33: 30
A34: 5 | B34: Motivational/Inspirational content | C34: 46216 | D34: 0.70833333 | E34: Ideas are common. Execution is the competitive advantage. Steve Jobs wasn't the first person to imagine a smartphone, tablet, or graphical computer. What made him legendary was his relentless focus on execution—turning ideas into products people loved. Apple's success wasn't built on having the most ideas; it was built on executing them better than almost anyone else. An idea has potential. Execution creates impact. (So i always have plenty of ideas but my summer internship at iNeuBytes teach me about the execution of idea, iNeuBytes give me task to Execute 30 posts in 14 days.) | F34: Visual Creative | G34: #iNeuBytes #iNeuBytesInternship #onlineInternship #Certificates #growth #Marketing #contentcreation #Ideas #Execution #Apple | H34: No design needed | J34: Completion % | K34: =K30/K33 -> 1
A35: 6 | B35: Educational Marketing graphic | C35: 46216 | D35: 0.75 | E35: TA-DUM. You probably heard that in your head before you even saw the Netflix logo. That's the power of sonic branding. Unlike a jingle, sonic branding doesn't need lyrics. Sometimes, just a few distinctive notes are enough to make millions of people instantly recognize a brand. Netflix's iconic "Ta-Dum" plays before every show, creating anticipation and reinforcing the brand with every watch. The best brands aren't remembered only by what they look like. They're remembered by what they sound like. In a world full of visual noise, the brands that win are often the ones people can recognize with their eyes closed. A logo identifies a brand. A sound makes it unforgettable. What's the first sonic logo that comes to your mind? (Sound and brand identity like this is the kind of marketing detail I've studied closely during my Digital Marketing internship at iNeuBytes.) | F35: Visual Creative | G35: #iNeuBytes #Onlineinternship #iNeuBytesinternship #contentcreation #freemarketing #Marketing #Branding #SonicBranding #Netflix #AudioBranding #Advertising #BrandStrategy | H35: No design needed
A36: 7 | B36: Infographics | C36: 46217 | D36: 0.70833333 | E36: Most SEO audits fail because people use only one tool. These 5 free SEO tools cover almost everything—from technical SEO to page speed and indexing. Save this post before your next website audit. (Has been using these tools for my iNeuBytes internship.) | F36: Visual Creative | G36: #iNeuBytes #iNeubytesintership #onlineinternship #contentcreation #Marketing #SEO #SEOTOOLS #Free #Website #Digitalmarketing | H36: No design needed
A37: 8 | B37: Infographics | C37: 46217 | D37: 0.75 | E37: India's biggest food delivery battle isn't fought in restaurants. It's fought in technology, logistics, and execution. Zomato vs Swiggy isn't just a rivalry—it's a masterclass in how competition drives innovation. From food delivery to quick commerce, both companies keep pushing each other to build better products, faster deliveries, and better customer experiences. One question remains... Which side are you on—Zomato or Swiggy? 🍕🛵 Breaking down real brand rivalries like this is exactly the kind of competitive analysis I've been doing during my Digital Marketing internship at iNeuBytes. | F37: Social Media Creative/Visual Creative | G37: #iNeuBytes #iNeuBytesinternship #onlineinternship #Digitalmarketing #Marketing #Rivalry #Food #Zomato #Swiggy #Business #Startup #Entrepreneurship #Marketing #Innovation #India #Tech #LinkedIn | H37: No design needed
A38: 9 | B38: Case Studies/Testimonials | C38: 46218 | D38: 0.70833333 | E38: The biggest reason Amul is still winning after 70+ years? It never confused innovation with identity. Its products evolved. Its packaging evolved. Its marketing evolved. But its purpose never did. It changed everything. Except its purpose. That's the difference between building a product that sells and a brand that lasts. Which brand do you think has stayed true to its purpose the longest? (Case studies like this shape how iNeuBytes trains interns to think about brand purpose — grateful for that lens.) | F38: Visual Creative | G38: #iNeuBytes #iNeubytesinternship #OnlineInternship #DigitalMarketing #Marketing #Amul #butter #purpose #identity #brand #BrandStory | H38: No design needed
A39: 10 | B39: Carousels | C39: 46218 | D39: 0.75 | E39: More than just a certificate—it was real industry exposure. During my internship at INEUBYTES, I worked on practical, real-world tasks under the guidance of experienced mentors. The internship helped me strengthen my skills, gain hands-on experience, and build confidence while earning a certificate upon successful completion. | F39: Visual Creative | G39: #iNeuBytes #onlineintership #virtualinternship #iNeubytesinternship #Growth #contentcreation | H39: No design needed
A40: 11 | B40: Infographics | C40: 46218 | D40: 0.79166667 | E40: The best competition doesn't create losers. It creates better products. Jio changed the rules. Airtel changed its strategy. One disrupted. One adapted. India won. (This is the kind of strategic thinking iNeuBytes has been pushing me to apply during my internship.) | F40: Visual Creative | G40: #iNeuBytes #iNeuBytesinternship #onlineinternship #Digitalmarketing #Marketing #Contentcreator #Jio #Airtel #telecom | H40: No design needed
A41: 12 | B41: Case Studies/Testimonials | C41: 46219 | D41: 0.70833333 | E41: What if Google had never built Chrome? One internal idea changed the future of the web. Sundar Pichai believed Google needed its own browser—one that was faster, simpler, and more secure. Google listened. The result was Chrome, now the world's most-used web browser. Great products don't always start with a product. Sometimes, they start with one person's vision. (Exploring different stories for my #iNeubytes internship.) | F41: Visual Creative | G41: #Google #Chrome #TechHistory #Innovation #Leadership #Business #iNeubytes #Onlineinternship #digitalmarketing #Marketing #iNeubytesinternship | H41: No design needed
A42: 13 | B42: Infographics | C42: 46219 | D42: 0.75 | E42: Flipkart created Big Billion Days. Amazon answered with the Great Indian Festival. Every year, both brands compete with bigger deals, faster deliveries, and smarter strategies. Billions are spent for one thing: your click. Which side are you on—Amazon or Flipkart? (Analyzing real campaigns like this is part of what I've been learning hands-on during my iNeuBytes internship) | F42: Visual Creative | G42: #Amazon #Flipkart #Business #Ecommerce #Competition #Marketing #Innovation #BigBillionDays #GreatIndianFestival #iNeuBytes #onlineinternship #iNeuBytesinternship #DigitalMarketing #Marketing | H42: No design needed
...

Sheet Publish
A1: DAY | B1: DATE | C1: TIME | D1: CAPTION (CONTENT) | E1: LINK (POST IN YOUR LINKEDIN) AND PASTE THE LINK HERE | F1: STATUS
A2: THURDAY | B2: 45085 | C2: 17:00 PM | D2: 📣 Calling all aspiring data wizards! 🧙‍♂️✨ Level up your skills with our exclusive 3-month data science course 📊🔬 Join us on a journey of discovery as we unravel the secrets of data analysis, machine learning, and more 🌟💻 Unleash your potential and gain a competitive edge in the digital era 🚀💡 Don't miss out on this golden opportunity! Register now and let the data adventure begin! 📚💫 | E2: https://www.linkedin.com/posts/ineubytes_datascientist-datasciencetraining-machinelearning-activity-7072525201032282112-HY1y?utm_source=share&utm_medium=member_desktop | F2: Sample
A3: TO POST AT CORRECT TIME USE BUFFER AND SCHEDULE YOUR POSTS (OR) YOU CAN SCHEDULE YOUR POSTS IN LINKEDIN ALSO
A5: DAY | B5: DATE | C5: TIME | D5: CAPTION (CONTENT) | E5: LINK (POST IN YOUR LINKEDIN) AND PASTE THE LINK HERE | F5: STATUS
A6: 1 | B6: 46214 | C6: 0.70833333 | D6: Most businesses are sitting on diamonds. But without a polished social media presence, the world sees coal. Your product quality, your team, your vision — none of it matters if your online presence doesn't reflect it. Unpolished gems are treated like coals. The companies winning right now aren't always the best. They're the most visible. The most consistent. The ones who showed up online before they felt "ready." Your brand is the gem. Social media is the cutting and polishing. One makes you valuable. The other makes you seen. I learned while doing my #iNeuBytes internship That how much digital marketing is important for a brand. | E6: https://www.linkedin.com/posts/mohit-sukhija_ineubytes-ineubytes-brandvisibility-activity-7481693819051130880-KdKQ?utm_source=social_share_send&utm_medium=android_app&rcm=ACoAAGaFDK0BbyG1T-wOG0OIQPBDmmlKf9CNHpM&utm_campaign=copy_link | F6: Published
A7: 1 | B7: 46214 | C7: 0.75 | D7: I've seen people post once a week and explode. I've seen others post three times a day with almost no growth. The difference isn't luck. It's context. Every successful creator has a unique mix of audience, timing, brand, and experience. So before you copy someone's content strategy, ask yourself: Will this work for my audience—or am I just copying because it worked for someone else? The best strategy isn't borrowed. It's built. ( While doing Competitor analysis task for my #iNeuBytes internship i learned same content doesn't always work for different brands, every brand needs to find their own.) | E7: https://www.linkedin.com/posts/mohit-sukhija_ineubytes-ineubytes-contentcreator-activity-7481739080507187201-7sXn?utm_source=social_share_send&utm_medium=android_app&rcm=ACoAAGaFDK0BbyG1T-wOG0OIQPBDmmlKf9CNHpM&utm_campaign=copy_link | F7: Published
A8: 2 | B8: 46215 | C8: 0.70833333 | D8: Everybody knows the line: "Have a break, have a KitKat." But have you ever wondered why you still remember it years later? That's the power of a great jingle. A jingle isn't just a catchy tune or phrase. It's a memory trigger. It helps people recognize a brand, creates familiarity, and makes advertisements stick long after they're over. When done right, a jingle turns marketing into memory. That's why some of the most successful brands invest in creating sounds and phrases people can instantly recall. People may forget an advertisement. They rarely forget a great jingle. What's the first brand jingle that comes to your mind? (While Doing my iNeuBytes internship i realised that the most engaging thing about an advertisement is not just its design, content and hook the music the jingle and sound branding also matters.) | E8: https://www.linkedin.com/posts/mohit-sukhija_ineubytes-onlineinternship-ineubytesintership-activity-7482063727001878528-BoLi?utm_source=social_share_send&utm_medium=android_app&rcm=ACoAAGaFDK0BbyG1T-wOG0OIQPBDmmlKf9CNHpM&utm_campaign=copy_link | F8: Published
A9: 2 | B9: 46215 | C9: 0.75 | D9: Think of it this way: 📜 Certificates are your entry pass. 🛠️ Skills are your toolkit. 📈 Experience is your proof. Without the pass, some doors stay closed. Without the toolkit, you can't do the work. Without experience, it's difficult to earn trust. Build all three—but spend most of your time sharpening your skills. (Thanks to my iNeuBytes internship, I understand the difference between holding a certificate and having a skill.) | E9: https://www.linkedin.com/posts/mohit-sukhija_ineubytes-internship-certificates-activity-7482101470532923392-Ht3u?utm_source=social_share_send&utm_medium=android_app&rcm=ACoAAGaFDK0BbyG1T-wOG0OIQPBDmmlKf9CNHpM&utm_campaign=copy_link | F9: Published
A10: 3 | B10: 46216 | C10: 0.70833333 | D10: Ideas are common. Execution is the competitive advantage. Steve Jobs wasn't the first person to imagine a smartphone, tablet, or graphical computer. What made him legendary was his relentless focus on execution—turning ideas into products people loved. Apple's success wasn't built on having the most ideas; it was built on executing them better than almost anyone else. An idea has potential. Execution creates impact. (So i always have plenty of ideas but my summer internship at iNeuBytes teach me about the execution of idea, iNeuBytes give me task to Execute 30 posts in 14 days.) | E10: https://www.linkedin.com/posts/mohit-sukhija_ineubytes-ineubytesinternship-onlineinternship-activity-7482426149864841216-xmLC?utm_source=social_share_send&utm_medium=android_app&rcm=ACoAAGaFDK0BbyG1T-wOG0OIQPBDmmlKf9CNHpM&utm_campaign=copy_link | F10: Published
A11: 3 | B11: 46216 | C11: 0.75 | D11: TA-DUM. You probably heard that in your head before you even saw the Netflix logo. That's the power of sonic branding. Unlike a jingle, sonic branding doesn't need lyrics. Sometimes, just a few distinctive notes are enough to make millions of people instantly recognize a brand. Netflix's iconic "Ta-Dum" plays before every show, creating anticipation and reinforcing the brand with every watch. The best brands aren't remembered only by what they look like. They're remembered by what they sound like. In a world full of visual noise, the brands that win are often the ones people can recognize with their eyes closed. A logo identifies a brand. A sound makes it unforgettable. What's the first sonic logo that comes to your mind? (Sound and brand identity like this is the kind of marketing detail I've studied closely during my Digital Marketing internship at iNeuBytes.) | E11: https://www.linkedin.com/posts/mohit-sukhija_ineubytes-onlineinternship-ineubytesinternship-activity-7482463901285130240-AOnc?utm_source=social_share_send&utm_medium=android_app&rcm=ACoAAGaFDK0BbyG1T-wOG0OIQPBDmmlKf9CNHpM&utm_campaign=copy_link | F11: Published
A12: 4 | B12: 46217 | C12: 0.70833333 | D12: Most SEO audits fail because people use only one tool. These 5 free SEO tools cover almost everything—from technical SEO to page speed and indexing. Save this post before your next website audit. (Has been using these tools for my iNeuBytes internship.) | E12: https://www.linkedin.com/posts/mohit-sukhija_ineubytes-ineubytesintership-onlineinternship-activity-7482701443544600576-tFCQ?utm_source=social_share_send&utm_medium=android_app&rcm=ACoAAGaFDK0BbyG1T-wOG0OIQPBDmmlKf9CNHpM&utm_campaign=copy_link | F12: Published
A13: 4 | B13: 46217 | C13: 0.75 | D13: India's biggest food delivery battle isn't fought in restaurants. It's fought in technology, logistics, and execution. Zomato vs Swiggy isn't just a rivalry—it's a masterclass in how competition drives innovation. From food delivery to quick commerce, both companies keep pushing each other to build better products, faster deliveries, and better customer experiences. One question remains... Which side are you on—Zomato or Swiggy? 🍕🛵 Breaking down real brand rivalries like this is exactly the kind of competitive analysis I've been doing during my Digital Marketing internship at iNeuBytes. | E13: https://www.linkedin.com/posts/mohit-sukhija_ineubytes-ineubytesinternship-onlineinternship-activity-7482826340757426176-a1s_?utm_source=social_share_send&utm_medium=android_app&rcm=ACoAAGaFDK0BbyG1T-wOG0OIQPBDmmlKf9CNHpM&utm_campaign=copy_link | F13: Published
A14: 5 | B14: 46218 | C14: 0.70833333 | D14: The biggest reason Amul is still winning after 70+ years? It never confused innovation with identity. Its products evolved. Its packaging evolved. Its marketing evolved. But its purpose never did. It changed everything. Except its purpose. That's the difference between building a product that sells and a brand that lasts. Which brand do you think has stayed true to its purpose the longest? (Case studies like this shape how iNeuBytes trains interns to think about brand purpose — grateful for that lens.) | E14: https://www.linkedin.com/posts/mohit-sukhija_ineubytes-ineubytesinternship-onlineinternship-activity-7483158475489951744-hxPh?utm_source=social_share_send&utm_medium=android_app&rcm=ACoAAGaFDK0BbyG1T-wOG0OIQPBDmmlKf9CNHpM&utm_campaign=copy_link | F14: Published
A15: 5 | B15: 46218 | C15: 0.75 | D15: More than just a certificate—it was real industry exposure. During my internship at INEUBYTES, I worked on practical, real-world tasks under the guidance of experienced mentors. The internship helped me strengthen my skills, gain hands-on experience, and build confidence while earning a certificate upon successful completion. | E15: https://www.linkedin.com/posts/mohit-sukhija_ineubytes-onlineintership-virtualinternship-activity-7483181097917366272-8ZcP?utm_source=social_share_send&utm_medium=android_app&rcm=ACoAAGaFDK0BbyG1T-wOG0OIQPBDmmlKf9CNHpM&utm_campaign=copy_link | F15: Published
A16: 5 | B16: 46218 | C16: 0.79166667 | D16: The best competition doesn't create losers. It creates better products. Jio changed the rules. Airtel changed its strategy. One disrupted. One adapted. India won. (This is the kind of strategic thinking iNeuBytes has been pushing me to apply during my internship.) | E16: https://www.linkedin.com/posts/mohit-sukhija_ineubytes-ineubytesinternship-onlineinternship-activity-7483188783400529920-JkDY?utm_source=social_share_send&utm_medium=android_app&rcm=ACoAAGaFDK0BbyG1T-wOG0OIQPBDmmlKf9CNHpM&utm_campaign=copy_link | F16: Published
A17: 6 | B17: 46219 | C17: 0.70833333 | D17: What if Google had never built Chrome? One internal idea changed the future of the web. Sundar Pichai believed Google needed its own browser—one that was faster, simpler, and more secure. Google listened. The result was Chrome, now the world's most-used web browser. Great products don't always start with a product. Sometimes, they start with one person's vision. (Exploring different stories for my #iNeubytes internship.) | E17: https://www.linkedin.com/posts/mohit-sukhija_ineubytes-google-chrome-activity-7483513326409248769-BkIx?utm_source=social_share_send&utm_medium=android_app&rcm=ACoAAGaFDK0BbyG1T-wOG0OIQPBDmmlKf9CNHpM&utm_campaign=copy_link | F17: Published
... A35: 13 | B35: 46226 | C35: 0.41666667 | D35: People often say internships help you gain experience. But I think the real purpose of an internship is much simpler: An internship exists to turn theoretical knowledge into practical experience. For the past 30 days as a Digital Marketing Intern at iNeuBytes, I got the opportunity to apply what I had only learned in classrooms. I worked on content creation, explored SEO tools, created LinkedIn posts, learned digital marketing strategies, met deadlines, accepted feedback, and most importantly, understood how real work actually happens. One moment I'm especially proud of? A piece of content I created crossed 100,000+ impressions. It reminded me that consistent effort and continuous learning always pay off. I'm grateful to the entire iNeuBytes team for giving me this opportunity and for creating an environment where learning comes from doing. This internship may have ended, but the lessons and confidence I gained will stay with me for a long time. Once again thankyou iNeuBytes for this experiences. Here's to learning, growing, and taking the next step. 🚀 | E35: https://www.linkedin.com/posts/mohit-sukhija_internship-ineubytes-digitalmarketing-activity-7485914097075748865-bz2g?utm_source=social_share_send&utm_medium=android_app&rcm=ACoAAGaFDK0BbyG1T-wOG0OIQPBDmmlKf9CNHpM&utm_campaign=copy_link | F35: Published
